Workbook

Sheet Szenarien
A1: Szenarienvergleich – Normaljahr
A3: Kennzahl | B3: Einheit | C3: pessimistisch | D3: Basis | E3: optimistisch
A4: Besuche pro Jahr | B4: Besuche | C4: =Umsatz!C6 -> 36000 | D4: =Umsatz!D6 -> 47120 | E4: =Umsatz!E6 -> 57215
A5: Ø Besucher/Tag Hauptsaison | B5: Besucher | C5: =Annahmen!$C$10 -> 140 | D5: =Annahmen!$D$10 -> 180 | E5: =Annahmen!$E$10 -> 215
A6: Umsatz netto | B6: € | C6: =Umsatz!C16 -> 1315174.2 | D6: =Umsatz!D16 -> 1934607.6 | E6: =Umsatz!E16 -> 2593479.2
A7: Umsatz je Besuch | B7: € | C7: =Umsatz!C17 -> 36.532615 | D7: =Umsatz!D17 -> 41.057038 | E7: =Umsatz!E17 -> 45.328659
A8: Betriebskosten vor Pacht | B8: € | C8: =Betriebskosten!C13 -> 1723301.8 | D8: =Betriebskosten!D13 -> 1752636.1 | E8: =Betriebskosten!E13 -> 1859371.5
A9: Pacht an Gemeinde-GmbH | B9: € | C9: =Betriebskosten!C15 -> 150000 | D9: =Betriebskosten!D15 -> 193460.76 | E9: =Betriebskosten!E15 -> 259347.92
A10: Betreiberergebnis (EBITDA) | B10: € | C10: =Betriebskosten!C16 -> -558127.6 | D10: =Betriebskosten!D16 -> -11489.228 | E10: =Betriebskosten!E16 -> 474759.8
A11: EBITDA-Marge | B11: % | C11: =Betriebskosten!C18 -> -0.42437543 | D11: =Betriebskosten!D18 -> -0.0059387898 | E11: =Betriebskosten!E18 -> 0.18305904
A12: Break-even Besuche (Betreiber) | B12: Besuche | C12: =Betriebskosten!C24 -> 57649.426 | D12: =Betriebskosten!D24 -> 47525.975 | E12: =Betriebskosten!E24 -> 42122.218
A13: Break-even in % der Planbesuche | B13: % | C13: =Betriebskosten!C25 -> 1.601373 | D13: =Betriebskosten!D25 -> 1.0086158 | E13: =Betriebskosten!E25 -> 0.73620935
A14: Überschuss Gemeinde-GmbH p. a. (Pacht – Rücklage – Verwaltung) | B14: € | C14: =Betriebskosten!C15-Investition!$F$49*Annahmen!$C$45-Annahmen!$C$46 -> 70096 | D14: =Betriebskosten!D15-Investition!$F$49*Annahmen!$D$45-Annahmen!$D$46 -> 113556.76 | E14: =Betriebskosten!E15-Investition!$F$49*Annahmen!$E$45-Annahmen!$E$46 -> 179443.92
A15: Gemeinde-Investition (netto nach Förderung) | B15: € | C15: =Investition!$F$58 -> 8557224.8 | D15: =Investition!$F$58 -> 8557224.8 | E15: =Investition!$F$58 -> 8557224.8
A16: Rückflussdauer aus Pacht (statisch) | B16: Jahre | C16: =IF(C14>0,Investition!$F$58/C14,"n/a") -> 122.07865 | D16: =IF(D14>0,Investition!$F$58/D14,"n/a") -> 75.356363 | E16: =IF(E14>0,Investition!$F$58/E14,"n/a") -> 47.68746
A17: Tragbarer Pachtsatz (bei Ziel-Marge Betreiber) | B17: % | C17: =MAX(0,Betriebskosten!C14/Umsatz!C16-Annahmen!$C$43) -> 0 | D17: =MAX(0,Betriebskosten!D14/Umsatz!D16-Annahmen!$D$43) -> 0.01406121 | E17: =MAX(0,Betriebskosten!E14/Umsatz!E16-Annahmen!$E$43) -> 0.20305904
A18: Tragbare Pacht p. a. | B18: € | C18: =C17*Umsatz!C16 -> 0 | D18: =D17*Umsatz!D16 -> 27202.925 | E18: =E17*Umsatz!E16 -> 526629.39
A21: Lesart: Die Pacht deckt Instandhaltung und einen Teil der Investition (Teil-Tilgung). Eine Vollrefinanzierung über die Pacht ist nicht vorgesehen – der Rest ist Standort- und Tourismusinfrastruktur der Gemeinden (Umwegrentabilität: Kommunalsteuer, Nächtigungen, Ganzjahresangebot).

Sheet Annahmen
A1: Seesauna Attersee – Annahmen (Rahmenkonzept, Stand Oktober 2026)
A2: Legende: blaue Zahlen = Eingaben (änderbar) · schwarz = Formeln · grün = Verweise auf andere Blätter · gelb hinterlegt = Schlüsselannahmen. Szenario in C4 wählen (1 = pessimistisch, 2 = Basis, 3 = optimistisch).
B4: Aktives Szenario (1/2/3) | C4: 2 | D4: =INDEX({"pessimistisch","Basis","optimistisch"},1,C4) -> Basis
A6: Key | B6: Annahme | C6: pessimistisch | D6: Basis | E6: optimistisch | F6: aktiv | G6: Einheit | H6: Quelle / Hinweis
B7: Kapazität & Besuch
A8: tage_hs | B8: Öffnungstage Hauptsaison (Okt–Apr, abzgl. 7 Revisionstage) | C8: =D8 -> 205 | D8: 205 | E8: =D8 -> 205 | F8: =INDEX(C8:E8,1,$C$4) -> 205 | G8: Tage | H8: Ganzjahresbetrieb lt. Grilling; 212 Tage Okt–Apr minus Revision
A9: tage_ns | B9: Öffnungstage Nebensaison (Mai–Sep, abzgl. 7 Tage) | C9: =D9 -> 146 | D9: 146 | E9: =D9 -> 146 | F9: =INDEX(C9:E9,1,$C$4) -> 146 | G9: Tage | H9: Im Sommer reduzierte Zeiten / Kombi mit Strandbad
A10: g_hs | B10: Ø Besucher pro Tag Hauptsaison | C10: 140 | D10: 180 | E10: 215 | F10: =INDEX(C10:E10,1,$C$4) -> 180 | G10: Besucher | H10: Annahme; ~1,5 Belegungswechsel bei 120 Gleichzeitig-Plätzen
A11: g_ns | B11: Ø Besucher pro Tag Nebensaison | C11: 50 | D11: 70 | E11: 90 | F11: =INDEX(C11:E11,1,$C$4) -> 70 | G11: Besucher | H11: Annahme; Sommer schwach, Seezugang + Strandbad-Kombi als Treiber
A12: kap | B12: Max. Besucher pro Tag (Spitzentag) | C12: =D12 -> 300 | D12: 300 | E12: =D12 -> 300 | F12: =INDEX(C12:E12,1,$C$4) -> 300 | G12: Besucher | H12: 120 gleichzeitig × ~2,5 Wechsel
B13: Preise (brutto, inkl. USt)
A14: p_tag | B14: Tageskarte | C14: 36 | D14: 39 | E14: 42 | F14: =INDEX(C14:E14,1,$C$4) -> 39 | G14: € | H14: Zielband 35–42 € lt. Grilling (gehobene Mitte)
A15: p_3h | B15: 3-Stunden-Karte | C15: 23 | D15: 25 | E15: 27 | F15: =INDEX(C15:E15,1,$C$4) -> 25 | G15: € | H15: lt. Grilling ca. 25 €
A16: a_tag | B16: Anteil Tageskarten an Besuchen | C16: =D16 -> 0.55 | D16: 0.55 | E16: =D16 -> 0.55 | F16: =INDEX(C16:E16,1,$C$4) -> 0.55 | G16: % | H16: Annahme
A17: rabatt | B17: Ø Rabatt (Abos, Einheimischentarif, Hotelkontingente) | C17: 0.15 | D17: 0.12 | E17: 0.1 | F17: =INDEX(C17:E17,1,$C$4) -> 0.12 | G17: % | H17: Annahme; Einheimischentarif als Auflage der Gemeinden
A18: ust_e | B18: USt-Satz Eintritt | C18: =D18 -> 0.13 | D18: 0.13 | E18: =D18 -> 0.13 | F18: =INDEX(C18:E18,1,$C$4) -> 0.13 | G18: % | H18: Annahme ermäßigter Satz für Bäder/Saunen – steuerlich prüfen
B19: Gastronomie & Zusatzerlöse
A20: g_kopf | B20: Gastro-Umsatz pro Besucher (brutto) | C20: 11 | D20: 12.5 | E20: 14 | F20: =INDEX(C20:E20,1,$C$4) -> 12.5 | G20: € | H20: Branchenüblich 8–15 € (Bistro, kleine Karte)
A21: ust_g | B21: Ø USt-Satz Gastro (Mix 10 %/20 %) | C21: =D21 -> 0.15 | D21: 0.15 | E21: =D21 -> 0.15 | F21: =INDEX(C21:E21,1,$C$4) -> 0.15 | G21: % | H21: Speisen 10 %, Getränke 20 %
A22: we_g | B22: Wareneinsatzquote Gastro | C22: =D22 -> 0.32 | D22: 0.32 | E22: =D22 -> 0.32 | F22: =INDEX(C22:E22,1,$C$4) -> 0.32 | G22: % | H22: Branchenwert Bistro 28–35 %
A23: kiosk | B23: Strandbad-Kiosk Sommer (Umsatz netto) | C23: 45000 | D23: 60000 | E23: 75000 | F23: =INDEX(C23:E23,1,$C$4) -> 60000 | G23: €/Jahr | H23: Annahme; Betreiber übernimmt Kiosk Mai–Sep
A24: we_k | B24: Wareneinsatzquote Kiosk | C24: =D24 -> 0.4 | D24: 0.4 | E24: =D24 -> 0.4 | F24: =INDEX(C24:E24,1,$C$4) -> 0.4 | G24: % | H24: Annahme
A25: m_anz | B25: Massagebehandlungen pro Jahr (2 Räume) | C25: 3000 | D25: 4000 | E25: 5000 | F25: =INDEX(C25:E25,1,$C$4) -> 4000 | G25: Stück | H25: Annahme; freie Masseur:innen
A26: m_preis | B26: Ø Preis Massage (brutto) | C26: =D26 -> 75 | D26: 75 | E26: =D26 -> 75 | F26: =INDEX(C26:E26,1,$C$4) -> 75 | G26: € | H26: Annahme
A27: ust_m | B27: USt-Satz Massage | C27: =D27 -> 0.2 | D27: 0.2 | E27: =D27 -> 0.2 | F27: =INDEX(C27:E27,1,$C$4) -> 0.2 | G27: % | H27: Normalsteuersatz
A28: m_prov | B28: Provision / Raummiete an Betreiber | C28: =D28 -> 0.25 | D28: 0.25 | E28: =D28 -> 0.25 | F28: =INDEX(C28:E28,1,$C$4) -> 0.25 | G28: % | H28: Annahme; Anteil am Netto-Behandlungsumsatz
A29: ev_anz | B29: Events & Exklusivbuchungen pro Jahr | C29: 25 | D29: 40 | E29: 55 | F29: =INDEX(C29:E29,1,$C$4) -> 40 | G29: Stück | H29: Vollmond-/Themenaufgüsse, Firmen-Buyouts
A30: ev_erl | B30: Ø Zusatzerlös je Event (netto) | C30: =D30 -> 2500 | D30: 2500 | E30: =D30 -> 2500 | F30: =INDEX(C30:E30,1,$C$4) -> 2500 | G30: € | H30: Annahme
B31: Betriebskosten Betreiber
A32: fte | B32: Personal (Vollzeitäquivalente) | C32: 21 | D32: 20 | E32: 20 | F32: =INDEX(C32:E32,1,$C$4) -> 20 | G32: VZÄ | H32: Kassa 4, Saunameister:innen 5, Reinigung 4, Gastro 5, Leitung/Technik 2
A33: k_fte | B33: Personalkosten je VZÄ (inkl. Lohnnebenkosten) | C33: =D33 -> 52000 | D33: 52000 | E33: =D33 -> 52000 | F33: =INDEX(C33:E33,1,$C$4) -> 52000 | G33: €/Jahr | H33: Annahme KV Freizeitbetriebe/Gastro OÖ inkl. LNK
A34: energie | B34: Energiekosten (Seethermie-WP + PV + Holz) | C34: 220000 | D34: 180000 | E34: 160000 | F34: =INDEX(C34:E34,1,$C$4) -> 180000 | G34: €/Jahr | H34: Annahme; ohne Seethermie/PV eher 300–400 Tsd. €
A35: wasser | B35: Wasser / Abwasser | C35: =D35 -> 40000 | D35: 40000 | E35: =D35 -> 40000 | F35: =INDEX(C35:E35,1,$C$4) -> 40000 | G35: €/Jahr | H35: Annahme
A36: waesche | B36: Wäsche, Reinigungs- & Verbrauchsmaterial je Besuch | C36: =D36 -> 2.2 | D36: 2.2 | E36: =D36 -> 2.2 | F36: =INDEX(C36:E36,1,$C$4) -> 2.2 | G36: € | H36: Annahme
A37: mkt | B37: Marketing (in % vom Umsatz) | C37: =D37 -> 0.04 | D37: 0.04 | E37: =D37 -> 0.04 | F37: =INDEX(C37:E37,1,$C$4) -> 0.04 | G37: % | H37: Annahme
A38: wart | B38: Laufende Wartung Betreiber (in % vom Umsatz) | C38: =D38 -> 0.02 | D38: 0.02 | E38: =D38 -> 0.02 | F38: =INDEX(C38:E38,1,$C$4) -> 0.02 | G38: % | H38: Kleinreparaturen; große Instandhaltung = Gemeinde-GmbH
A39: verw | B39: Verwaltung, Versicherung, IT, Beratung | C39: =D39 -> 85000 | D39: 85000 | E39: =D39 -> 85000 | F39: =INDEX(C39:E39,1,$C$4) -> 85000 | G39: €/Jahr | H39: Annahme
B40: Pachtvertrag (Gemeinde-GmbH → Betreiber)
A41: p_satz | B41: Umsatzpacht (in % vom Nettoumsatz) | C41: =D41 -> 0.1 | D41: 0.1 | E41: =D41 -> 0.1 | F41: =INDEX(C41:E41,1,$C$4) -> 0.1 | G41: % | H41: Zielband 8–12 % lt. Grilling
A42: p_min | B42: Mindestpacht | C42: =D42 -> 150000 | D42: 150000 | E42: =D42 -> 150000 | F42: =INDEX(C42:E42,1,$C$4) -> 150000 | G42: €/Jahr | H42: Annahme; Absicherung der Gemeinden
...

Sheet Raumprogramm
A1: Raumprogramm (Nutzflächen)
A3: Bereich | B3: Nutzfläche (m²) | C3: Plätze | D3: Erläuterung
A4: Eingang, Kassa, Shop-Ecke | B4: 60 | D4: Zutrittssystem mit Chip-Armband, Gutscheinverkauf
A5: Garderobe & Umkleiden (Spinde) | B5: 140 | C5: 180 | D5: 180 Spinde für 120 Gleichzeitig-Gäste + Wechsel
A6: Sanitär & Duschen | B6: 100 | D6: Getrennte Duschzonen, Saunavorduschen
A7: Panorama-Aufgusssauna 90 °C | B7: 55 | C7: 35 | D7: Event-Aufgüsse, Glasfront Seeblick
A8: Bio-Sauna 60 °C | B8: 25 | C8: 12 | D8: Sanfte Sauna, Farblicht
A9: Dampfbad | B9: 22 | C9: 10 | D9: Inkl. Technikraum Dampferzeuger
A10: Holzofen-Saunahaus am Steg (außen) | B10: 30 | C10: 15 | D10: Separates Häuschen, direkter Seezugang
A11: Abkühlbereich innen (Tauchbecken, Kneipp, Schwallduschen) | B11: 70 | D11: Tauchbecken ca. 6 m²
A12: Ruheraum (Stille) | B12: 200 | C12: 50 | D12: 50 Liegen à ~4 m², Seeblick
A13: Kommunikationsraum (Liegen, Gespräche erlaubt) | B13: 200 | C13: 50 | D13: 50 Liegen, Kamin, Bibliothek
A14: Bistro (Gastraum + Theke) | B14: 90 | C14: 40 | D14: Im Bademantel; Terrasse saisonal zusätzlich
A15: Bistro-Küche (Regenerierküche) & Lager | B15: 50 | D15: Kleine Karte, 3–4 warme Gerichte
A16: Massage-/Behandlungsräume | B16: 40 | C16: 2 | D16: 2 Räume à 20 m²
A17: Personal, Büro, Sozialräume | B17: 55
A18: Haustechnik, Wäsche, Lager | B18: 150 | D18: Wärmepumpe, Lüftung, Wasseraufbereitung
A19: Verkehrsflächen | B19: 140 | D19: Gänge, Treppen
A20: Summe Nutzfläche (NF) | B20: =SUM(B4:B19) -> 1427
A21: Faktor BGF / NF | B21: 1.18 | D21: Annahme kompakter Holzbau (Wände, Schächte)
A22: Brutto-Grundfläche (BGF) | B22: =ROUND(B20*B21,-1) -> 1680
A24: Saunaplätze gesamt (Kontrolle) | C24: =C7+C8+C9+C10 -> 72
A25: Liegeplätze Ruhe + Kommunikation | C25: =C12+C13 -> 100

Sheet Investition
A1: Einmalige Investition (netto, exkl. USt – Vorsteuerabzug über Vermietung der Gemeinde-GmbH)
A3: KG | B3: Position | C3: Menge | D3: Einheit | E3: Einheitspreis (€) | F3: Summe (€) | G3: Hinweis
A4: 1 | B4: Aufschließung
B5: Erschließung, Parkplatzanpassung, Leitungen | C5: 1 | D5: psch | E5: 200000 | F5: =C5*E5 -> 200000 | G5: Strandbad-Infrastruktur teilweise vorhanden
B6: Abbruch / Anpassung Bestand Strandbad | C6: 1 | D6: psch | E6: 100000 | F6: =C6*E6 -> 100000
B7: Summe KG 1 | F7: =SUM(F5:F6) -> 300000
A9: 2 | B9: Bauwerk – Rohbau
B10: Holzbau-Rohbau inkl. Fundierung, Dach | C10: =Raumprogramm!$B$22 -> 1680 | D10: m² | E10: 1100 | F10: =C10*E10 -> 1848000 | G10: Regionaler Holzbau (CLT/Holzrahmen)
B11: Summe KG 2 | F11: =SUM(F10:F10) -> 1848000
A13: 3 | B13: Bauwerk – Technik
B14: Haustechnik HLS, Lüftung, Elektro | C14: =Raumprogramm!$B$22 -> 1680 | D14: m² | E14: 900 | F14: =C14*E14 -> 1512000 | G14: Hohe Lüftungs-/Feuchteanforderungen
B15: Seewasser-Wärmepumpe inkl. Entnahme/Rückgabe | C15: 1 | D15: psch | E15: 450000 | F15: =C15*E15 -> 450000 | G15: Wasserrechtliche Bewilligung nötig
B16: Photovoltaik | C16: 150 | D16: kWp | E16: 1100 | F16: =C16*E16 -> 165000 | G16: Dachfläche ca. 800 m²
B17: Wasseraufbereitung Tauchbecken/Whirlpool | C17: 1 | D17: psch | E17: 120000 | F17: =C17*E17 -> 120000 | G17: ÖNORM M 6215 / Bäderhygienegesetz
B18: Summe KG 3 | F18: =SUM(F14:F17) -> 2247000
A20: 4 | B20: Bauwerk – Ausbau
B21: Innenausbau, Glasfronten, Oberflächen | C21: =Raumprogramm!$B$22 -> 1680 | D21: m² | E21: 1100 | F21: =C21*E21 -> 1848000 | G21: Gehobener Standard, große Seeverglasung
B22: Panorama-Aufgusssauna (35 Plätze) | C22: 1 | D22: Stk | E22: 260000 | F22: =C22*E22 -> 260000 | G22: Inkl. Ofen, Steuerung, Glasfront
B23: Bio-Sauna (12 Plätze) | C23: 1 | D23: Stk | E23: 80000 | F23: =C23*E23 -> 80000
B24: Dampfbad (10 Plätze) | C24: 1 | D24: Stk | E24: 130000 | F24: =C24*E24 -> 130000 | G24: Inkl. Dampferzeuger, Fliesen/Mineralwerkstoff
B25: Holzofen-Saunahaus am Steg (15 Plätze) | C25: 1 | D25: Stk | E25: 220000 | F25: =C25*E25 -> 220000 | G25: Massivholz, holzbefeuert, Funkenschutz
B26: Tauchbecken innen | C26: 1 | D26: Stk | E26: 80000 | F26: =C26*E26 -> 80000
B27: Außen-Whirlpool (ca. 12 Personen) | C27: 1 | D27: Stk | E27: 150000 | F27: =C27*E27 -> 150000 | G27: Beheizt über Wärmepumpe
B28: Summe KG 4 | F28: =SUM(F21:F27) -> 2768000
A30: 5 | B30: Einrichtung
B31: Liegen (Ruhe, Kommunikation, Garten) | C31: 130 | D31: Stk | E31: 900 | F31: =C31*E31 -> 117000 | G31: Hochwertige Relaxliegen
B32: Gastro-Küche & Theke | C32: 1 | D32: psch | E32: 180000 | F32: =C32*E32 -> 180000 | G32: Regenerierküche, Kühlung, Kaffeetechnik
B33: Möblierung, Deko, Leitsystem | C33: 1 | D33: psch | E33: 200000 | F33: =C33*E33 -> 200000
B34: Kassen-/Zutrittssystem, Spinde, IT | C34: 1 | D34: psch | E34: 200000 | F34: =C34*E34 -> 200000 | G34: Chip-Armband, Online-Ticketing
B35: Summe KG 5 | F35: =SUM(F31:F34) -> 697000
A37: 6 | B37: Außenanlagen
B38: Saunagarten, Sichtschutz zum Strandbad, Wege | C38: 1 | D38: psch | E38: 300000 | F38: =C38*E38 -> 300000 | G38: Textilfrei → Sichtschutz zwingend
B39: Steg / Seezugang (ganzjährig, Leiter, Beleuchtung) | C39: 1 | D39: psch | E39: 250000 | F39: =C39*E39 -> 250000 | G39: Wasserrecht, Schifffahrt, Naturschutz
B40: Summe KG 6 | F40: =SUM(F38:F39) -> 550000
B42: Zwischensumme KG 1–6 | F42: =F7+F11+F18+F28+F35+F40 -> 8410000
A43: 7 | B43: Planungsleistungen (Architektur, Fachplanung, ÖBA) | E43: 0.15 | F43: =F42*E43 -> 1261500 | G43: Anteil an KG 1–6; Richtwert 14–18 %
A44: 8 | B44: Nebenleistungen (Gutachten, Genehmigungen, Projektsteuerung) | E44: 0.03 | F44: =F42*E44 -> 252300 | G44: Wasserrecht, Naturschutz, Bodengutachten, Bauherrenvertretung
A45: 9 | B45: Reserve (Unvorhergesehenes, Indexierung) | E45: 0.12 | F45: =(F42+F43+F44)*E45 -> 1190856 | G45: Konzeptphase: 10–15 % üblich
B46: GESAMTINVESTITION netto | F46: =F42+F43+F44+F45 -> 11114656
B47: je m² BGF | F47: =F46/Raumprogramm!$B$22 -> 6615.8667
...

Sheet Umsatz
A1: Umsatz Betreiber – Normaljahr (ab Jahr 3, Preisbasis Eröffnung, netto)
A3: Position | B3: Einheit | C3: pessimistisch | D3: Basis | E3: optimistisch | F3: aktiv
A4: Besuche Hauptsaison | B4: Besuche | C4: =Annahmen!$C$8*Annahmen!$C$10 -> 28700 | D4: =Annahmen!$D$8*Annahmen!$D$10 -> 36900 | E4: =Annahmen!$E$8*Annahmen!$E$10 -> 44075 | F4: =INDEX(C4:E4,1,Annahmen!$C$4) -> 36900
A5: Besuche Nebensaison | B5: Besuche | C5: =Annahmen!$C$9*Annahmen!$C$11 -> 7300 | D5: =Annahmen!$D$9*Annahmen!$D$11 -> 10220 | E5: =Annahmen!$E$9*Annahmen!$E$11 -> 13140 | F5: =INDEX(C5:E5,1,Annahmen!$C$4) -> 10220
A6: Besuche gesamt | B6: Besuche | C6: =C4+C5 -> 36000 | D6: =D4+D5 -> 47120 | E6: =E4+E5 -> 57215 | F6: =INDEX(C6:E6,1,Annahmen!$C$4) -> 47120
A7: Auslastung Hauptsaison (Ø / Spitzentag) | B7: % | C7: =Annahmen!$C$10/Annahmen!$C$12 -> 0.46666667 | D7: =Annahmen!$D$10/Annahmen!$D$12 -> 0.6 | E7: =Annahmen!$E$10/Annahmen!$E$12 -> 0.71666667 | F7: =INDEX(C7:E7,1,Annahmen!$C$4) -> 0.6
A8: Ø Eintritt je Besuch brutto | B8: € | C8: =(Annahmen!$C$16*Annahmen!$C$14+(1-Annahmen!$C$16)*Annahmen!$C$15)*(1-Annahmen!$C$17) -> 25.6275 | D8: =(Annahmen!$D$16*Annahmen!$D$14+(1-Annahmen!$D$16)*Annahmen!$D$15)*(1-Annahmen!$D$17) -> 28.776 | E8: =(Annahmen!$E$16*Annahmen!$E$14+(1-Annahmen!$E$16)*Annahmen!$E$15)*(1-Annahmen!$E$17) -> 31.725 | F8: =INDEX(C8:E8,1,Annahmen!$C$4) -> 28.776
A9: Ø Eintritt je Besuch netto | B9: € | C9: =C8/(1+Annahmen!$C$18) -> 22.679204 | D9: =D8/(1+Annahmen!$D$18) -> 25.465487 | E9: =E8/(1+Annahmen!$E$18) -> 28.075221 | F9: =INDEX(C9:E9,1,Annahmen!$C$4) -> 25.465487
A11: Eintrittserlöse | B11: € | C11: =C6*C9 -> 816451.33 | D11: =D6*D9 -> 1199933.7 | E11: =E6*E9 -> 1606323.8 | F11: =INDEX(C11:E11,1,Annahmen!$C$4) -> 1199933.7
A12: Gastronomie (Bistro) | B12: € | C12: =C6*Annahmen!$C$20/(1+Annahmen!$C$21) -> 344347.83 | D12: =D6*Annahmen!$D$20/(1+Annahmen!$D$21) -> 512173.91 | E12: =E6*Annahmen!$E$20/(1+Annahmen!$E$21) -> 696530.43 | F12: =INDEX(C12:E12,1,Annahmen!$C$4) -> 512173.91
A13: Strandbad-Kiosk (Sommer) | B13: € | C13: =Annahmen!$C$23 -> 45000 | D13: =Annahmen!$D$23 -> 60000 | E13: =Annahmen!$E$23 -> 75000 | F13: =INDEX(C13:E13,1,Annahmen!$C$4) -> 60000
A14: Massage (Provision/Raummiete) | B14: € | C14: =Annahmen!$C$25*Annahmen!$C$26/(1+Annahmen!$C$27)*Annahmen!$C$28 -> 46875 | D14: =Annahmen!$D$25*Annahmen!$D$26/(1+Annahmen!$D$27)*Annahmen!$D$28 -> 62500 | E14: =Annahmen!$E$25*Annahmen!$E$26/(1+Annahmen!$E$27)*Annahmen!$E$28 -> 78125 | F14: =INDEX(C14:E14,1,Annahmen!$C$4) -> 62500
A15: Events & Exklusivbuchungen | B15: € | C15: =Annahmen!$C$29*Annahmen!$C$30 -> 62500 | D15: =Annahmen!$D$29*Annahmen!$D$30 -> 100000 | E15: =Annahmen!$E$29*Annahmen!$E$30 -> 137500 | F15: =INDEX(C15:E15,1,Annahmen!$C$4) -> 100000
A16: UMSATZ GESAMT (netto) | B16: € | C16: =SUM(C11:C15) -> 1315174.2 | D16: =SUM(D11:D15) -> 1934607.6 | E16: =SUM(E11:E15) -> 2593479.2 | F16: =INDEX(C16:E16,1,Annahmen!$C$4) -> 1934607.6
A17: Umsatz je Besuch | B17: € | C17: =C16/C6 -> 36.532615 | D17: =D16/D6 -> 41.057038 | E17: =E16/E6 -> 45.328659 | F17: =INDEX(C17:E17,1,Annahmen!$C$4) -> 41.057038

Sheet Betriebskosten
A1: Betriebskosten & Ergebnis Betreiber – Normaljahr (netto)
A3: Position | B3: Art | C3: pessimistisch | D3: Basis | E3: optimistisch | F3: aktiv
A4: Wareneinsatz Gastro | B4: variabel | C4: =Umsatz!C12*Annahmen!$C$22 -> 110191.3 | D4: =Umsatz!D12*Annahmen!$D$22 -> 163895.65 | E4: =Umsatz!E12*Annahmen!$E$22 -> 222889.74 | F4: =INDEX(C4:E4,1,Annahmen!$C$4) -> 163895.65
A5: Wareneinsatz Kiosk | B5: variabel | C5: =Umsatz!C13*Annahmen!$C$24 -> 18000 | D5: =Umsatz!D13*Annahmen!$D$24 -> 24000 | E5: =Umsatz!E13*Annahmen!$E$24 -> 30000 | F5: =INDEX(C5:E5,1,Annahmen!$C$4) -> 24000
A6: Personal | B6: fix | C6: =Annahmen!$C$32*Annahmen!$C$33 -> 1092000 | D6: =Annahmen!$D$32*Annahmen!$D$33 -> 1040000 | E6: =Annahmen!$E$32*Annahmen!$E$33 -> 1040000 | F6: =INDEX(C6:E6,1,Annahmen!$C$4) -> 1040000
A7: Energie | B7: fix | C7: =Annahmen!$C$34 -> 220000 | D7: =Annahmen!$D$34 -> 180000 | E7: =Annahmen!$E$34 -> 160000 | F7: =INDEX(C7:E7,1,Annahmen!$C$4) -> 180000
A8: Wasser / Abwasser | B8: fix | C8: =Annahmen!$C$35 -> 40000 | D8: =Annahmen!$D$35 -> 40000 | E8: =Annahmen!$E$35 -> 40000 | F8: =INDEX(C8:E8,1,Annahmen!$C$4) -> 40000
A9: Wäsche, Reinigung, Verbrauchsmaterial | B9: variabel | C9: =Umsatz!C6*Annahmen!$C$36 -> 79200 | D9: =Umsatz!D6*Annahmen!$D$36 -> 103664 | E9: =Umsatz!E6*Annahmen!$E$36 -> 125873 | F9: =INDEX(C9:E9,1,Annahmen!$C$4) -> 103664
A10: Marketing | B10: variabel | C10: =Umsatz!C16*Annahmen!$C$37 -> 52606.966 | D10: =Umsatz!D16*Annahmen!$D$37 -> 77384.306 | E10: =Umsatz!E16*Annahmen!$E$37 -> 103739.17 | F10: =INDEX(C10:E10,1,Annahmen!$C$4) -> 77384.306
A11: Laufende Wartung | B11: variabel | C11: =Umsatz!C16*Annahmen!$C$38 -> 26303.483 | D11: =Umsatz!D16*Annahmen!$D$38 -> 38692.153 | E11: =Umsatz!E16*Annahmen!$E$38 -> 51869.584 | F11: =INDEX(C11:E11,1,Annahmen!$C$4) -> 38692.153
A12: Verwaltung, Versicherung, IT | B12: fix | C12: =Annahmen!$C$39 -> 85000 | D12: =Annahmen!$D$39 -> 85000 | E12: =Annahmen!$E$39 -> 85000 | F12: =INDEX(C12:E12,1,Annahmen!$C$4) -> 85000
A13: BETRIEBSKOSTEN vor Pacht | C13: =SUM(C4:C12) -> 1723301.8 | D13: =SUM(D4:D12) -> 1752636.1 | E13: =SUM(E4:E12) -> 1859371.5 | F13: =INDEX(C13:E13,1,Annahmen!$C$4) -> 1752636.1
A14: Ergebnis vor Pacht (EBITDAR) | C14: =Umsatz!C16-C13 -> -408127.6 | D14: =Umsatz!D16-D13 -> 181971.54 | E14: =Umsatz!E16-E13 -> 734107.73 | F14: =INDEX(C14:E14,1,Annahmen!$C$4) -> 181971.54
A15: Pacht an Gemeinde-GmbH | C15: =MAX(Annahmen!$C$42,Annahmen!$C$41*Umsatz!C16) -> 150000 | D15: =MAX(Annahmen!$D$42,Annahmen!$D$41*Umsatz!D16) -> 193460.76 | E15: =MAX(Annahmen!$E$42,Annahmen!$E$41*Umsatz!E16) -> 259347.92 | F15: =INDEX(C15:E15,1,Annahmen!$C$4) -> 193460.76
A16: BETREIBERERGEBNIS nach Pacht (EBITDA) | C16: =C14-C15 -> -558127.6 | D16: =D14-D15 -> -11489.228 | E16: =E14-E15 -> 474759.8 | F16: =INDEX(C16:E16,1,Annahmen!$C$4) -> -11489.228
A18: EBITDA-Marge | B18: % | C18: =C16/Umsatz!C16 -> -0.42437543 | D18: =D16/Umsatz!D16 -> -0.0059387898 | E18: =E16/Umsatz!E16 -> 0.18305904 | F18: =INDEX(C18:E18,1,Annahmen!$C$4) -> -0.0059387898
A19: Personalkostenquote | B19: % | C19: =C6/Umsatz!C16 -> 0.83030829 | D19: =D6/Umsatz!D16 -> 0.5375767 | E19: =E6/Umsatz!E16 -> 0.40100572 | F19: =INDEX(C19:E19,1,Annahmen!$C$4) -> 0.5375767
A20: Energiekostenquote | B20: % | C20: =C7/Umsatz!C16 -> 0.16727823 | D20: =D7/Umsatz!D16 -> 0.093042122 | E20: =E7/Umsatz!E16 -> 0.061693188 | F20: =INDEX(C20:E20,1,Annahmen!$C$4) -> 0.093042122
A21: Pachtquote | B21: % | C21: =C15/Umsatz!C16 -> 0.11405334 | D21: =D15/Umsatz!D16 -> 0.1 | E21: =E15/Umsatz!E16 -> 0.1 | F21: =INDEX(C21:E21,1,Annahmen!$C$4) -> 0.1
A22: Fixkosten (Personal, Energie, Wasser, Verwaltung) | C22: =C6+C7+C8+C12 -> 1437000 | D22: =D6+D7+D8+D12 -> 1345000 | E22: =E6+E7+E8+E12 -> 1325000 | F22: =INDEX(C22:E22,1,Annahmen!$C$4) -> 1345000
A23: Deckungsbeitrag je Besuch (nach Umsatzpacht) | B23: € | C23: =(Umsatz!C16*(1-Annahmen!$C$41)-C4-C5-C9-C10-C11)/Umsatz!C6 -> 24.926527 | D23: =(Umsatz!D16*(1-Annahmen!$D$41)-D4-D5-D9-D10-D11)/Umsatz!D6 -> 28.300313 | E23: =(Umsatz!E16*(1-Annahmen!$E$41)-E4-E5-E9-E10-E11)/Umsatz!E6 -> 31.456083 | F23: =INDEX(C23:E23,1,Annahmen!$C$4) -> 28.300313
A24: Break-even Besuche pro Jahr (Betreiber) | B24: Besuche | C24: =C22/C23 -> 57649.426 | D24: =D22/D23 -> 47525.975 | E24: =E22/E23 -> 42122.218 | F24: =INDEX(C24:E24,1,Annahmen!$C$4) -> 47525.975
A25: Break-even in % der geplanten Besuche | B25: % | C25: =C24/Umsatz!C6 -> 1.601373 | D25: =D24/Umsatz!D6 -> 1.0086158 | E25: =E24/Umsatz!E6 -> 0.73620935 | F25: =INDEX(C25:E25,1,Annahmen!$C$4) -> 1.0086158

Sheet GuV_10J
A1: Betreiber-GuV & Pachtfluss – 10 Jahre (aktives Szenario, nominal)
A2: ="Szenario: "&Annahmen!D4 -> Szenario: Basis
A4: € | B4: J1 | C4: J2 | D4: J3 | E4: J4 | F4: J5 | G4: J6 | H4: J7 | I4: J8 | J4: J9 | K4: J10
A5: Kalenderjahr | B5: =TEXT(Annahmen!$F$50+0,"0") -> 2029 | C5: =TEXT(Annahmen!$F$50+1,"0") -> 2030 | D5: =TEXT(Annahmen!$F$50+2,"0") -> 2031 | E5: =TEXT(Annahmen!$F$50+3,"0") -> 2032 | F5: =TEXT(Annahmen!$F$50+4,"0") -> 2033 | G5: =TEXT(Annahmen!$F$50+5,"0") -> 2034 | H5: =TEXT(Annahmen!$F$50+6,"0") -> 2035 | I5: =TEXT(Annahmen!$F$50+7,"0") -> 2036 | J5: =TEXT(Annahmen!$F$50+8,"0") -> 2037 | K5: =TEXT(Annahmen!$F$50+9,"0") -> 2038
A6: Hochlauf-Faktor | B6: =Annahmen!$F$51 -> 0.75 | C6: =Annahmen!$F$52 -> 0.9 | D6: =1 -> 1 | E6: =1 -> 1 | F6: =1 -> 1 | G6: =1 -> 1 | H6: =1 -> 1 | I6: =1 -> 1 | J6: =1 -> 1 | K6: =1 -> 1
A7: Preisindex | B7: =(1+Annahmen!$F$53)^0 -> 1 | C7: =(1+Annahmen!$F$53)^1 -> 1.025 | D7: =(1+Annahmen!$F$53)^2 -> 1.050625 | E7: =(1+Annahmen!$F$53)^3 -> 1.0768906 | F7: =(1+Annahmen!$F$53)^4 -> 1.1038129 | G7: =(1+Annahmen!$F$53)^5 -> 1.1314082 | H7: =(1+Annahmen!$F$53)^6 -> 1.1596934 | I7: =(1+Annahmen!$F$53)^7 -> 1.1886858 | J7: =(1+Annahmen!$F$53)^8 -> 1.2184029 | K7: =(1+Annahmen!$F$53)^9 -> 1.248863
A8: Kostenindex | B8: =(1+Annahmen!$F$54)^0 -> 1 | C8: =(1+Annahmen!$F$54)^1 -> 1.03 | D8: =(1+Annahmen!$F$54)^2 -> 1.0609 | E8: =(1+Annahmen!$F$54)^3 -> 1.092727 | F8: =(1+Annahmen!$F$54)^4 -> 1.1255088 | G8: =(1+Annahmen!$F$54)^5 -> 1.1592741 | H8: =(1+Annahmen!$F$54)^6 -> 1.1940523 | I8: =(1+Annahmen!$F$54)^7 -> 1.2298739 | J8: =(1+Annahmen!$F$54)^8 -> 1.2667701 | K8: =(1+Annahmen!$F$54)^9 -> 1.3047732
A9: Besuche | B9: =Umsatz!F6*B6 -> 35340 | C9: =Umsatz!F6*C6 -> 42408 | D9: =Umsatz!F6*D6 -> 47120 | E9: =Umsatz!F6*E6 -> 47120 | F9: =Umsatz!F6*F6 -> 47120 | G9: =Umsatz!F6*G6 -> 47120 | H9: =Umsatz!F6*H6 -> 47120 | I9: =Umsatz!F6*I6 -> 47120 | J9: =Umsatz!F6*J6 -> 47120 | K9: =Umsatz!F6*K6 -> 47120
A10: Umsatz netto | B10: =Umsatz!F16*B6*B7 -> 1450955.7 | C10: =Umsatz!F16*C6*C7 -> 1784675.6 | D10: =Umsatz!F16*D6*D7 -> 2032547.2 | E10: =Umsatz!F16*E6*E7 -> 2083360.8 | F10: =Umsatz!F16*F6*F7 -> 2135444.9 | G10: =Umsatz!F16*G6*G7 -> 2188831 | H10: =Umsatz!F16*H6*H7 -> 2243551.8 | I10: =Umsatz!F16*I6*I7 -> 2299640.5 | J10: =Umsatz!F16*J6*J7 -> 2357131.6 | K10: =Umsatz!F16*K6*K7 -> 2416059.9
A11: Variable Kosten (Wareneinsatz, Wäsche, Mkt, Wartung) | B11: =(Betriebskosten!F4+Betriebskosten!F5+Betriebskosten!F9+Betriebskosten!F10+Betriebskosten!F11)*B6*B8 -> 305727.08 | C11: =(Betriebskosten!F4+Betriebskosten!F5+Betriebskosten!F9+Betriebskosten!F10+Betriebskosten!F11)*C6*C8 -> 377878.67 | D11: =(Betriebskosten!F4+Betriebskosten!F5+Betriebskosten!F9+Betriebskosten!F10+Betriebskosten!F11)*D6*D8 -> 432461.15 | E11: =(Betriebskosten!F4+Betriebskosten!F5+Betriebskosten!F9+Betriebskosten!F10+Betriebskosten!F11)*E6*E8 -> 445434.98 | F11: =(Betriebskosten!F4+Betriebskosten!F5+Betriebskosten!F9+Betriebskosten!F10+Betriebskosten!F11)*F6*F8 -> 458798.03 | G11: =(Betriebskosten!F4+Betriebskosten!F5+Betriebskosten!F9+Betriebskosten!F10+Betriebskosten!F11)*G6*G8 -> 472561.98 | H11: =(Betriebskosten!F4+Betriebskosten!F5+Betriebskosten!F9+Betriebskosten!F10+Betriebskosten!F11)*H6*H8 -> 486738.83 | I11: =(Betriebskosten!F4+Betriebskosten!F5+Betriebskosten!F9+Betriebskosten!F10+Betriebskosten!F11)*I6*I8 -> 501341 | J11: =(Betriebskosten!F4+Betriebskosten!F5+Betriebskosten!F9+Betriebskosten!F10+Betriebskosten!F11)*J6*J8 -> 516381.23 | K11: =(Betriebskosten!F4+Betriebskosten!F5+Betriebskosten!F9+Betriebskosten!F10+Betriebskosten!F11)*K6*K8 -> 531872.67
A12: Fixkosten (Personal, Energie, Wasser, Verwaltung) | B12: =Betriebskosten!F22*B8 -> 1345000 | C12: =Betriebskosten!F22*C8 -> 1385350 | D12: =Betriebskosten!F22*D8 -> 1426910.5 | E12: =Betriebskosten!F22*E8 -> 1469717.8 | F12: =Betriebskosten!F22*F8 -> 1513809.3 | G12: =Betriebskosten!F22*G8 -> 1559223.6 | H12: =Betriebskosten!F22*H8 -> 1606000.3 | I12: =Betriebskosten!F22*I8 -> 1654180.3 | J12: =Betriebskosten!F22*J8 -> 1703805.8 | K12: =Betriebskosten!F22*K8 -> 1754919.9
A13: Ergebnis vor Pacht | B13: =B10-B11-B12 -> -199771.35 | C13: =C10-C11-C12 -> 21446.88 | D13: =D10-D11-D12 -> 173175.51 | E13: =E10-E11-E12 -> 168208.04 | F13: =F10-F11-F12 -> 162837.48 | G13: =G10-G11-G12 -> 157045.38 | H13: =H10-H11-H12 -> 150812.58 | I13: =I10-I11-I12 -> 144119.2 | ... K13: =K10-K11-K12 -> 129267.25
A14: Pacht | B14: =MAX(Annahmen!$F$42*B8,Annahmen!$F$41*B10) -> 150000 | C14: =MAX(Annahmen!$F$42*C8,Annahmen!$F$41*C10) -> 178467.56 | D14: =MAX(Annahmen!$F$42*D8,Annahmen!$F$41*D10) -> 203254.72 | E14: =MAX(Annahmen!$F$42*E8,Annahmen!$F$41*E10) -> 208336.08 | F14: =MAX(Annahmen!$F$42*F8,Annahmen!$F$41*F10) -> 213544.49 | G14: =MAX(Annahmen!$F$42*G8,Annahmen!$F$41*G10) -> 218883.1 | H14: =MAX(Annahmen!$F$42*H8,Annahmen!$F$41*H10) -> 224355.18 | I14: =MAX(Annahmen!$F$42*I8,Annahmen!$F$41*I10) -> 229964.05 | ... K14: =MAX(Annahmen!$F$42*K8,Annahmen!$F$41*K10) -> 241605.99
A15: Betreiberergebnis (EBITDA) | B15: =B13-B14 -> -349771.35 | C15: =C13-C14 -> -157020.68 | D15: =D13-D14 -> -30079.206 | E15: =E13-E14 -> -40128.045 | F15: =F13-F14 -> -50707.01 | G15: =G13-G14 -> -61837.722 | H15: =H13-H14 -> -73542.593 | I15: =I13-I14 -> -85844.854 | ... K15: =K13-K14 -> -112338.73
A16: Betreiberergebnis kumuliert | B16: =B15 -> -349771.35 | C16: =B16+C15 -> -506792.02 | D16: =C16+D15 -> -536871.23 | E16: =D16+E15 -> -576999.27 | F16: =E16+F15 -> -627706.28 | G16: =F16+G15 -> -689544.01 | H16: =G16+H15 -> -763086.6 | I16: =H16+I15 -> -848931.45 | J16: =I16+J15 -> -947700.04 | K16: =J16+K15 -> -1060038.8
A17: Gemeinde-Errichtungs-GmbH
A18: Pachteinnahme | B18: =B14 -> 150000 | C18: =C14 -> 178467.56 | D18: =D14 -> 203254.72 | E18: =E14 -> 208336.08 | F18: =F14 -> 213544.49 | G18: =G14 -> 218883.1 | H18: =H14 -> 224355.18 | I18: =I14 -> 229964.05 | ... K18: =K14 -> 241605.99
A19: Instandhaltungsrücklage | B19: =-Investition!$F$49*Annahmen!$F$45*B8 -> -54904 | C19: =-Investition!$F$49*Annahmen!$F$45*C8 -> -56551.12 | D19: =-Investition!$F$49*Annahmen!$F$45*D8 -> -58247.654 | E19: =-Investition!$F$49*Annahmen!$F$45*E8 -> -59995.083 | F19: =-Investition!$F$49*Annahmen!$F$45*F8 -> -61794.936 | G19: =-Investition!$F$49*Annahmen!$F$45*G8 -> -63648.784 | H19: =-Investition!$F$49*Annahmen!$F$45*H8 -> -65558.247 | I19: =-Investition!$F$49*Annahmen!$F$45*I8 -> -67524.995 | ... K19: =-Investition!$F$49*Annahmen!$F$45*K8 -> -71637.267
A20: Verwaltung GmbH | B20: =-Annahmen!$F$46*B8 -> -25000 | C20: =-Annahmen!$F$46*C8 -> -25750 | D20: =-Annahmen!$F$46*D8 -> -26522.5 | E20: =-Annahmen!$F$46*E8 -> -27318.175 | F20: =-Annahmen!$F$46*F8 -> -28137.72 | G20: =-Annahmen!$F$46*G8 -> -28981.852 | H20: =-Annahmen!$F$46*H8 -> -29851.307 | I20: =-Annahmen!$F$46*I8 -> -30746.847 | ... K20: =-Annahmen!$F$46*K8 -> -32619.33
A21: Überschuss für Rückführung an Gemeinden | B21: =SUM(B18:B20) -> 70096 | C21: =SUM(C18:C20) -> 96166.435 | D21: =SUM(D18:D20) -> 118484.56 | E21: =SUM(E18:E20) -> 121022.83 | F21: =SUM(F18:F20) -> 123611.83 | G21: =SUM(G18:G20) -> 126252.46 | H21: =SUM(H18:H20) -> 128945.62 | I21: =SUM(I18:I20) -> 131692.21 | ... K21: =SUM(K18:K20) -> 137349.39
A22: Rückfluss kumuliert | B22: =B21 -> 70096 | C22: =B22+C21 -> 166262.44 | D22: =C22+D21 -> 284747 | E22: =D22+E21 -> 405769.82 | F22: =E22+F21 -> 529381.65 | G22: =F22+G21 -> 655634.12 | H22: =G22+H21 -> 784579.74 | I22: =H22+I21 -> 916271.95 | J22: =I22+J21 -> 1050765.1 | K22: =J22+K21 -> 1188114.5
A23: Kommunalsteuer an Standortgemeinde (zusätzlich) | B23: =Betriebskosten!F6*Annahmen!$F$48*Annahmen!$F$47*B8 -> 23712 | C23: =Betriebskosten!F6*Annahmen!$F$48*Annahmen!$F$47*C8 -> 24423.36 | D23: =Betriebskosten!F6*Annahmen!$F$48*Annahmen!$F$47*D8 -> 25156.061 | E23: =Betriebskosten!F6*Annahmen!$F$48*Annahmen!$F$47*E8 -> 25910.743 | F23: =Betriebskosten!F6*Annahmen!$F$48*Annahmen!$F$47*F8 -> 26688.065 | G23: =Betriebskosten!F6*Annahmen!$F$48*Annahmen!$F$47*G8 -> 27488.707 | H23: =Betriebskosten!F6*Annahmen!$F$48*Annahmen!$F$47*H8 -> 28313.368 | I23: =Betriebskosten!F6*Annahmen!$F$48*Annahmen!$F$47*I8 -> 29162.769 | J23: =Betriebskosten!F6*Annahmen!$F$48*Annahmen!$F$47*J8 -> 30037.652 | K23: =Betriebskosten!F6*Annahmen!$F$48*Annahmen!$F$47*K8 -> 30938.782
A25: Summe Rückfluss 10 Jahre | B25: =SUM(B21:K21) -> 1188114.5
A26: Rückflussquote 10 J. auf Gemeinde-Investition | B26: =B25/Investition!$F$58 -> 0.13884344

Sheet Gemeinden
A1: Aufteilung der einmaligen Investition auf Gemeinden & TVB
A2: Einwohner- und Nächtigungszahlen sind GROBE PLATZHALTER und vor Verwendung mit Statistik Austria (Bevölkerung 1.1., Tourismusstatistik) bzw. Land OÖ zu ersetzen. Standortgemeinde mit 'x' markieren.
A4: Zu verteilende Investition (netto nach Förderung) | D4: =Investition!$F$58 -> 8557224.8
A5: Anteil Tourismusverband Attersee-Attergau | D5: 0.1 | E5: Begründung: TVB profitiert über Nächtigungen/Angebot
A6: Bonus-Anteil Standortgemeinde | D6: 0.15 | E6: Begründung: Kommunalsteuer, Frequenz, Aufwertung Strandbad
A7: Gewichtung Einwohner (Rest = Nächtigungen) | D7: 0.5
A9: Gemeinde | B9: Einwohner | C9: Nächtigungen/Jahr | D9: Standort (x) | E9: Anteil | F9: Einmalbetrag (€) | G9: Ø Pachtrückfluss p. a. (€) | H9: € je Einwohner
A10: Seewalchen am Attersee | B10: 5700 | C10: 75000 | E10: =(1-$D$5-$D$6)*($D$7*B10/$B$17+(1-$D$7)*C10/$C$17)+IF(D10="x",$D$6,0) -> 0.18431393 | F10: =$D$4*E10 -> 1577215.8 | G10: =AVERAGE(GuV_10J!$B$21:$K$21)*E10/(1-$D$5) -> 24331.784 | H10: =F10/B10 -> 276.70452
A11: Schörfling am Attersee | B11: 3500 | C11: 45000 | E11: =(1-$D$5-$D$6)*($D$7*B11/$B$17+(1-$D$7)*C11/$C$17)+IF(D11="x",$D$6,0) -> 0.11245752 | F11: =$D$4*E11 -> 962324.27 | G11: =AVERAGE(GuV_10J!$B$21:$K$21)*E11/(1-$D$5) -> 14845.823 | H11: =F11/B11 -> 274.94979
A12: Attersee am Attersee | B12: 1650 | C12: 120000 | D12: x | E12: =(1-$D$5-$D$6)*($D$7*B12/$B$17+(1-$D$7)*C12/$C$17)+IF(D12="x",$D$6,0) -> 0.27036958 | F12: =$D$4*E12 -> 2313613.3 | G12: =AVERAGE(GuV_10J!$B$21:$K$21)*E12/(1-$D$5) -> 35692.225 | H12: =F12/B12 -> 1402.1899
A13: Weyregg am Attersee | B13: 1600 | C13: 100000 | E13: =(1-$D$5-$D$6)*($D$7*B13/$B$17+(1-$D$7)*C13/$C$17)+IF(D13="x",$D$6,0) -> 0.105565 | F13: =$D$4*E13 -> 903343.4 | G13: =AVERAGE(GuV_10J!$B$21:$K$21)*E13/(1-$D$5) -> 13935.922 | H13: =F13/B13 -> 564.58962
A14: Unterach am Attersee | B14: 1550 | C14: 75000 | E14: =(1-$D$5-$D$6)*($D$7*B14/$B$17+(1-$D$7)*C14/$C$17)+IF(D14="x",$D$6,0) -> 0.087351317 | F14: =$D$4*E14 -> 747484.86 | G14: =AVERAGE(GuV_10J!$B$21:$K$21)*E14/(1-$D$5) -> 11531.485 | H14: =F14/B14 -> 482.24829
A15: Nußdorf am Attersee | B15: 1200 | C15: 70000 | E15: =(1-$D$5-$D$6)*($D$7*B15/$B$17+(1-$D$7)*C15/$C$17)+IF(D15="x",$D$6,0) -> 0.075764656 | F15: =$D$4*E15 -> 648335.19 | G15: =AVERAGE(GuV_10J!$B$21:$K$21)*E15/(1-$D$5) -> 10001.898 | H15: =F15/B15 -> 540.27933
A16: Steinbach am Attersee | B16: 850 | C16: 65000 | E16: =(1-$D$5-$D$6)*($D$7*B16/$B$17+(1-$D$7)*C16/$C$17)+IF(D16="x",$D$6,0) -> 0.064177995 | F16: =$D$4*E16 -> 549185.53 | G16: =AVERAGE(GuV_10J!$B$21:$K$21)*E16/(1-$D$5) -> 8472.3118 | H16: =F16/B16 -> 646.10062
A17: Summe Gemeinden | B17: =SUM(B10:B16) -> 16050 | C17: =SUM(C10:C16) -> 550000 | E17: =SUM(E10:E16) -> 0.9 | F17: =SUM(F10:F16) -> 7701502.3 | G17: =SUM(G10:G16) -> 118811.45 | H17: =F17/B17 -> 479.84438
A18: Tourismusverband Attersee-Attergau | E18: =D5 -> 0.1 | F18: =$D$4*E18 -> 855722.48
A19: Kontrolle: Summe = zu verteilende Investition | E19: =E17+E18 -> 1 | F19: =F17+F18 -> 8557224.8 | G19: =IF(ABS(F19-D4)<1,"OK","FEHLER") -> OK
A21: Pachtrückfluss: Ø-Überschuss der Gemeinde-GmbH (GuV_10J) nach Gemeinde-Anteil verteilt; TVB-Anteil ohne Rückfluss angenommen (Zuschuss).
